[2022-09-15T10:00:44.913+0000] {taskinstance.py:1171} INFO - Dependencies all met for <TaskInstance: vecap_etl.date_dim manual__2022-09-15T10:00:42.309834+00:00 [queued]>
[2022-09-15T10:00:44.932+0000] {taskinstance.py:1171} INFO - Dependencies all met for <TaskInstance: vecap_etl.date_dim manual__2022-09-15T10:00:42.309834+00:00 [queued]>
[2022-09-15T10:00:44.933+0000] {taskinstance.py:1368} INFO - 
--------------------------------------------------------------------------------
[2022-09-15T10:00:44.934+0000] {taskinstance.py:1369} INFO - Starting attempt 1 of 1
[2022-09-15T10:00:44.935+0000] {taskinstance.py:1370} INFO - 
--------------------------------------------------------------------------------
[2022-09-15T10:00:44.967+0000] {taskinstance.py:1389} INFO - Executing <Task(PostgresOperator): date_dim> on 2022-09-15 10:00:42.309834+00:00
[2022-09-15T10:00:44.978+0000] {standard_task_runner.py:52} INFO - Started process 48083 to run task
[2022-09-15T10:00:44.989+0000] {standard_task_runner.py:79} INFO - Running: ['***', 'tasks', 'run', 'vecap_etl', 'date_dim', 'manual__2022-09-15T10:00:42.309834+00:00', '--job-id', '106', '--raw', '--subdir', 'DAGS_FOLDER/c_dag.py', '--cfg-path', '/tmp/tmp63ox5ngc', '--error-file', '/tmp/tmpm1c3nesq']
[2022-09-15T10:00:44.992+0000] {standard_task_runner.py:80} INFO - Job 106: Subtask date_dim
[2022-09-15T10:00:45.127+0000] {task_command.py:371} INFO - Running <TaskInstance: vecap_etl.date_dim manual__2022-09-15T10:00:42.309834+00:00 [running]> on host 0d275337f52b
[2022-09-15T10:00:45.213+0000] {taskinstance.py:1902} ERROR - Task failed with exception
Traceback (most recent call last):
  File "/home/airflow/.local/lib/python3.7/site-packages/airflow/models/taskinstance.py", line 1463, in _run_raw_task
    self._execute_task_with_callbacks(context, test_mode)
  File "/home/airflow/.local/lib/python3.7/site-packages/airflow/models/taskinstance.py", line 1567, in _execute_task_with_callbacks
    task_orig = self.render_templates(context=context)
  File "/home/airflow/.local/lib/python3.7/site-packages/airflow/models/taskinstance.py", line 2225, in render_templates
    rendered_task = self.task.render_template_fields(context)
  File "/home/airflow/.local/lib/python3.7/site-packages/airflow/models/baseoperator.py", line 1188, in render_template_fields
    self._do_render_template_fields(self, self.template_fields, context, jinja_env, set())
  File "/home/airflow/.local/lib/python3.7/site-packages/airflow/utils/session.py", line 71, in wrapper
    return func(*args, session=session, **kwargs)
  File "/home/airflow/.local/lib/python3.7/site-packages/airflow/models/abstractoperator.py", line 347, in _do_render_template_fields
    seen_oids,
  File "/home/airflow/.local/lib/python3.7/site-packages/airflow/models/abstractoperator.py", line 390, in render_template
    return render_template_to_string(template, context)
  File "/home/airflow/.local/lib/python3.7/site-packages/airflow/utils/helpers.py", line 298, in render_template_to_string
    return render_template(template, cast(MutableMapping[str, Any], context), native=False)
  File "/home/airflow/.local/lib/python3.7/site-packages/airflow/utils/helpers.py", line 293, in render_template
    return "".join(nodes)
  File "<template>", line 13, in root
  File "/home/airflow/.local/lib/python3.7/site-packages/jinja2/runtime.py", line 852, in _fail_with_undefined_error
    raise self._undefined_exception(self._undefined_message)
jinja2.exceptions.UndefinedError: 'dict object' has no attribute 'sch'
[2022-09-15T10:00:45.254+0000] {taskinstance.py:1412} INFO - Marking task as FAILED. dag_id=vecap_etl, task_id=date_dim, execution_date=20220915T100042, start_date=20220915T100044, end_date=20220915T100045
[2022-09-15T10:00:45.275+0000] {standard_task_runner.py:97} ERROR - Failed to execute job 106 for task date_dim ('dict object' has no attribute 'sch'; 48083)
[2022-09-15T10:00:45.320+0000] {local_task_job.py:156} INFO - Task exited with return code 1
