[2022-09-08T11:11:22.675+0000] {taskinstance.py:1171} INFO - Dependencies all met for <TaskInstance: test_etl.geo manual__2022-09-08T11:11:20.384155+00:00 [queued]>
[2022-09-08T11:11:22.688+0000] {taskinstance.py:1171} INFO - Dependencies all met for <TaskInstance: test_etl.geo manual__2022-09-08T11:11:20.384155+00:00 [queued]>
[2022-09-08T11:11:22.690+0000] {taskinstance.py:1368} INFO - 
--------------------------------------------------------------------------------
[2022-09-08T11:11:22.691+0000] {taskinstance.py:1369} INFO - Starting attempt 1 of 1
[2022-09-08T11:11:22.692+0000] {taskinstance.py:1370} INFO - 
--------------------------------------------------------------------------------
[2022-09-08T11:11:22.715+0000] {taskinstance.py:1389} INFO - Executing <Task(PythonOperator): geo> on 2022-09-08 11:11:20.384155+00:00
[2022-09-08T11:11:22.727+0000] {standard_task_runner.py:52} INFO - Started process 10111 to run task
[2022-09-08T11:11:22.736+0000] {standard_task_runner.py:79} INFO - Running: ['***', 'tasks', 'run', 'test_etl', 'geo', 'manual__2022-09-08T11:11:20.384155+00:00', '--job-id', '33', '--raw', '--subdir', 'DAGS_FOLDER/test_dag.py', '--cfg-path', '/tmp/tmp3u6p9cig', '--error-file', '/tmp/tmp4la5w4ic']
[2022-09-08T11:11:22.739+0000] {standard_task_runner.py:80} INFO - Job 33: Subtask geo
[2022-09-08T11:11:22.848+0000] {task_command.py:371} INFO - Running <TaskInstance: test_etl.geo manual__2022-09-08T11:11:20.384155+00:00 [running]> on host 0edf5f972c6d
[2022-09-08T11:11:22.953+0000] {taskinstance.py:1583} INFO - Exporting the following env vars:
AIRFLOW_CTX_DAG_EMAIL=admin@vecap.com
AIRFLOW_CTX_DAG_OWNER=***
AIRFLOW_CTX_DAG_ID=test_etl
AIRFLOW_CTX_TASK_ID=geo
AIRFLOW_CTX_EXECUTION_DATE=2022-09-08T11:11:20.384155+00:00
AIRFLOW_CTX_TRY_NUMBER=1
AIRFLOW_CTX_DAG_RUN_ID=manual__2022-09-08T11:11:20.384155+00:00
[2022-09-08T11:11:22.968+0000] {base.py:68} INFO - Using connection ID 'vecap_source' for task execution.
[2022-09-08T11:11:23.563+0000] {base.py:68} INFO - Using connection ID 'vecap_target' for task execution.
[2022-09-08T11:11:23.881+0000] {taskinstance.py:1902} ERROR - Task failed with exception
Traceback (most recent call last):
  File "/home/airflow/.local/lib/python3.7/site-packages/airflow/operators/python.py", line 171, in execute
    return_value = self.execute_callable()
  File "/home/airflow/.local/lib/python3.7/site-packages/airflow/operators/python.py", line 189, in execute_callable
    return self.python_callable(*self.op_args, **self.op_kwargs)
  File "/opt/airflow/dags/test_dag.py", line 44, in geo_dim
    dp = pd.read_sql(f'SELECT * from {schs}.person;', con= hook1)
  File "/home/airflow/.local/lib/python3.7/site-packages/pandas/io/sql.py", line 608, in read_sql
    chunksize=chunksize,
  File "/home/airflow/.local/lib/python3.7/site-packages/pandas/io/sql.py", line 2116, in read_query
    cursor = self.execute(*args)
  File "/home/airflow/.local/lib/python3.7/site-packages/pandas/io/sql.py", line 2054, in execute
    cur = self.con.cursor()
AttributeError: 'RedshiftSQLHook' object has no attribute 'cursor'
[2022-09-08T11:11:23.901+0000] {taskinstance.py:1412} INFO - Marking task as FAILED. dag_id=test_etl, task_id=geo, execution_date=20220908T111120, start_date=20220908T111122, end_date=20220908T111123
[2022-09-08T11:11:23.924+0000] {standard_task_runner.py:97} ERROR - Failed to execute job 33 for task geo ('RedshiftSQLHook' object has no attribute 'cursor'; 10111)
[2022-09-08T11:11:23.958+0000] {local_task_job.py:156} INFO - Task exited with return code 1
[2022-09-08T11:11:24.027+0000] {local_task_job.py:279} INFO - 0 downstream tasks scheduled from follow-on schedule check
