[2022-09-12T11:09:19.981+0000] {taskinstance.py:1171} INFO - Dependencies all met for <TaskInstance: vecap_etl.source_conn scheduled__2022-09-09T00:00:00+00:00 [queued]>
[2022-09-12T11:09:19.999+0000] {taskinstance.py:1171} INFO - Dependencies all met for <TaskInstance: vecap_etl.source_conn scheduled__2022-09-09T00:00:00+00:00 [queued]>
[2022-09-12T11:09:20.000+0000] {taskinstance.py:1368} INFO - 
--------------------------------------------------------------------------------
[2022-09-12T11:09:20.002+0000] {taskinstance.py:1369} INFO - Starting attempt 4 of 4
[2022-09-12T11:09:20.004+0000] {taskinstance.py:1370} INFO - 
--------------------------------------------------------------------------------
[2022-09-12T11:09:20.041+0000] {taskinstance.py:1389} INFO - Executing <Task(PythonOperator): source_conn> on 2022-09-09 00:00:00+00:00
[2022-09-12T11:09:20.055+0000] {standard_task_runner.py:52} INFO - Started process 4418 to run task
[2022-09-12T11:09:20.070+0000] {standard_task_runner.py:79} INFO - Running: ['***', 'tasks', 'run', 'vecap_etl', 'source_conn', 'scheduled__2022-09-09T00:00:00+00:00', '--job-id', '65', '--raw', '--subdir', 'DAGS_FOLDER/c_dag.py', '--cfg-path', '/tmp/tmp4u7rnreq', '--error-file', '/tmp/tmpre2hpqln']
[2022-09-12T11:09:20.080+0000] {standard_task_runner.py:80} INFO - Job 65: Subtask source_conn
[2022-09-12T11:09:20.223+0000] {task_command.py:371} INFO - Running <TaskInstance: vecap_etl.source_conn scheduled__2022-09-09T00:00:00+00:00 [running]> on host 0d275337f52b
[2022-09-12T11:09:20.368+0000] {taskinstance.py:1583} INFO - Exporting the following env vars:
AIRFLOW_CTX_DAG_EMAIL=admin@vecap.com
AIRFLOW_CTX_DAG_OWNER=***
AIRFLOW_CTX_DAG_ID=vecap_etl
AIRFLOW_CTX_TASK_ID=source_conn
AIRFLOW_CTX_EXECUTION_DATE=2022-09-09T00:00:00+00:00
AIRFLOW_CTX_TRY_NUMBER=4
AIRFLOW_CTX_DAG_RUN_ID=scheduled__2022-09-09T00:00:00+00:00
[2022-09-12T11:09:20.441+0000] {taskinstance.py:1902} ERROR - Task failed with exception
Traceback (most recent call last):
  File "/home/airflow/.local/lib/python3.7/site-packages/airflow/operators/python.py", line 171, in execute
    return_value = self.execute_callable()
  File "/home/airflow/.local/lib/python3.7/site-packages/airflow/operators/python.py", line 189, in execute_callable
    return self.python_callable(*self.op_args, **self.op_kwargs)
  File "/opt/airflow/dags/credential.py", line 14, in db_source_conn
    SourceConn = create_engine(source_postgres_str)
  File "<string>", line 2, in create_engine
  File "/home/airflow/.local/lib/python3.7/site-packages/sqlalchemy/util/deprecations.py", line 309, in warned
    return fn(*args, **kwargs)
  File "/home/airflow/.local/lib/python3.7/site-packages/sqlalchemy/engine/create.py", line 534, in create_engine
    entrypoint = u._get_entrypoint()
  File "/home/airflow/.local/lib/python3.7/site-packages/sqlalchemy/engine/url.py", line 645, in _get_entrypoint
    cls = registry.load(name)
  File "/home/airflow/.local/lib/python3.7/site-packages/sqlalchemy/util/langhelpers.py", line 344, in load
    "Can't load plugin: %s:%s" % (self.group, name)
sqlalchemy.exc.NoSuchModuleError: Can't load plugin: sqlalchemy.dialects:postgresql.psycop2
[2022-09-12T11:09:20.480+0000] {taskinstance.py:1412} INFO - Marking task as FAILED. dag_id=vecap_etl, task_id=source_conn, execution_date=20220909T000000, start_date=20220912T110919, end_date=20220912T110920
[2022-09-12T11:09:20.512+0000] {standard_task_runner.py:97} ERROR - Failed to execute job 65 for task source_conn (Can't load plugin: sqlalchemy.dialects:postgresql.psycop2; 4418)
[2022-09-12T11:09:20.561+0000] {local_task_job.py:156} INFO - Task exited with return code 1
[2022-09-12T11:09:20.720+0000] {local_task_job.py:279} INFO - 0 downstream tasks scheduled from follow-on schedule check
