[2022-09-12T10:46:24.596+0000] {taskinstance.py:1171} INFO - Dependencies all met for <TaskInstance: vecap_etl.source_conn scheduled__2022-09-09T00:00:00+00:00 [queued]>
[2022-09-12T10:46:24.739+0000] {taskinstance.py:1171} INFO - Dependencies all met for <TaskInstance: vecap_etl.source_conn scheduled__2022-09-09T00:00:00+00:00 [queued]>
[2022-09-12T10:46:24.747+0000] {taskinstance.py:1368} INFO - 
--------------------------------------------------------------------------------
[2022-09-12T10:46:24.748+0000] {taskinstance.py:1369} INFO - Starting attempt 1 of 4
[2022-09-12T10:46:24.749+0000] {taskinstance.py:1370} INFO - 
--------------------------------------------------------------------------------
[2022-09-12T10:46:24.873+0000] {taskinstance.py:1389} INFO - Executing <Task(PythonOperator): source_conn> on 2022-09-09 00:00:00+00:00
[2022-09-12T10:46:24.950+0000] {standard_task_runner.py:52} INFO - Started process 263 to run task
[2022-09-12T10:46:25.072+0000] {standard_task_runner.py:79} INFO - Running: ['***', 'tasks', 'run', 'vecap_etl', 'source_conn', 'scheduled__2022-09-09T00:00:00+00:00', '--job-id', '53', '--raw', '--subdir', 'DAGS_FOLDER/c_dag.py', '--cfg-path', '/tmp/tmpvg5poyke', '--error-file', '/tmp/tmpcg1axov9']
[2022-09-12T10:46:25.111+0000] {standard_task_runner.py:80} INFO - Job 53: Subtask source_conn
[2022-09-12T10:46:25.977+0000] {task_command.py:371} INFO - Running <TaskInstance: vecap_etl.source_conn scheduled__2022-09-09T00:00:00+00:00 [running]> on host 0edf5f972c6d
[2022-09-12T10:46:26.571+0000] {taskinstance.py:1583} INFO - Exporting the following env vars:
AIRFLOW_CTX_DAG_EMAIL=admin@vecap.com
AIRFLOW_CTX_DAG_OWNER=***
AIRFLOW_CTX_DAG_ID=vecap_etl
AIRFLOW_CTX_TASK_ID=source_conn
AIRFLOW_CTX_EXECUTION_DATE=2022-09-09T00:00:00+00:00
AIRFLOW_CTX_TRY_NUMBER=1
AIRFLOW_CTX_DAG_RUN_ID=scheduled__2022-09-09T00:00:00+00:00
[2022-09-12T10:46:26.647+0000] {taskinstance.py:1902} ERROR - Task failed with exception
Traceback (most recent call last):
  File "/home/airflow/.local/lib/python3.7/site-packages/airflow/operators/python.py", line 171, in execute
    return_value = self.execute_callable()
  File "/home/airflow/.local/lib/python3.7/site-packages/airflow/operators/python.py", line 189, in execute_callable
    return self.python_callable(*self.op_args, **self.op_kwargs)
  File "/opt/airflow/dags/credential.py", line 14, in db_source_conn
    SourceConn = create_engine(source_postgres_str)
  File "<string>", line 2, in create_engine
  File "/home/airflow/.local/lib/python3.7/site-packages/sqlalchemy/util/deprecations.py", line 309, in warned
    return fn(*args, **kwargs)
  File "/home/airflow/.local/lib/python3.7/site-packages/sqlalchemy/engine/create.py", line 534, in create_engine
    entrypoint = u._get_entrypoint()
  File "/home/airflow/.local/lib/python3.7/site-packages/sqlalchemy/engine/url.py", line 645, in _get_entrypoint
    cls = registry.load(name)
  File "/home/airflow/.local/lib/python3.7/site-packages/sqlalchemy/util/langhelpers.py", line 344, in load
    "Can't load plugin: %s:%s" % (self.group, name)
sqlalchemy.exc.NoSuchModuleError: Can't load plugin: sqlalchemy.dialects:postgresql.psycop2
[2022-09-12T10:46:26.692+0000] {taskinstance.py:1412} INFO - Marking task as UP_FOR_RETRY. dag_id=vecap_etl, task_id=source_conn, execution_date=20220909T000000, start_date=20220912T104624, end_date=20220912T104626
[2022-09-12T10:46:26.755+0000] {standard_task_runner.py:97} ERROR - Failed to execute job 53 for task source_conn (Can't load plugin: sqlalchemy.dialects:postgresql.psycop2; 263)
[2022-09-12T10:46:26.807+0000] {local_task_job.py:156} INFO - Task exited with return code 1
[2022-09-12T10:46:27.096+0000] {local_task_job.py:279} INFO - 0 downstream tasks scheduled from follow-on schedule check
