[2022-10-06T13:14:27.042+0000] {taskinstance.py:1171} INFO - Dependencies all met for <TaskInstance: vecap_etl.person_dim manual__2022-10-06T13:13:51.553392+00:00 [queued]>
[2022-10-06T13:14:27.057+0000] {taskinstance.py:1171} INFO - Dependencies all met for <TaskInstance: vecap_etl.person_dim manual__2022-10-06T13:13:51.553392+00:00 [queued]>
[2022-10-06T13:14:27.059+0000] {taskinstance.py:1368} INFO - 
--------------------------------------------------------------------------------
[2022-10-06T13:14:27.059+0000] {taskinstance.py:1369} INFO - Starting attempt 1 of 1
[2022-10-06T13:14:27.060+0000] {taskinstance.py:1370} INFO - 
--------------------------------------------------------------------------------
[2022-10-06T13:14:27.080+0000] {taskinstance.py:1389} INFO - Executing <Task(PythonOperator): person_dim> on 2022-10-06 13:13:51.553392+00:00
[2022-10-06T13:14:27.088+0000] {standard_task_runner.py:52} INFO - Started process 3211 to run task
[2022-10-06T13:14:27.093+0000] {standard_task_runner.py:79} INFO - Running: ['***', 'tasks', 'run', 'vecap_etl', 'person_dim', 'manual__2022-10-06T13:13:51.553392+00:00', '--job-id', '198', '--raw', '--subdir', 'DAGS_FOLDER/c_dag.py', '--cfg-path', '/tmp/tmpgx3vfrks', '--error-file', '/tmp/tmpvj9v687r']
[2022-10-06T13:14:27.096+0000] {standard_task_runner.py:80} INFO - Job 198: Subtask person_dim
[2022-10-06T13:14:27.192+0000] {task_command.py:371} INFO - Running <TaskInstance: vecap_etl.person_dim manual__2022-10-06T13:13:51.553392+00:00 [running]> on host a41ad1c55a2c
[2022-10-06T13:14:27.315+0000] {taskinstance.py:1583} INFO - Exporting the following env vars:
AIRFLOW_CTX_DAG_EMAIL=admin@vecap.com
AIRFLOW_CTX_DAG_OWNER=***
AIRFLOW_CTX_DAG_ID=vecap_etl
AIRFLOW_CTX_TASK_ID=person_dim
AIRFLOW_CTX_EXECUTION_DATE=2022-10-06T13:13:51.553392+00:00
AIRFLOW_CTX_TRY_NUMBER=1
AIRFLOW_CTX_DAG_RUN_ID=manual__2022-10-06T13:13:51.553392+00:00
[2022-10-06T13:14:40.595+0000] {taskinstance.py:1902} ERROR - Task failed with exception
Traceback (most recent call last):
  File "/home/airflow/.local/lib/python3.7/site-packages/airflow/operators/python.py", line 171, in execute
    return_value = self.execute_callable()
  File "/home/airflow/.local/lib/python3.7/site-packages/airflow/operators/python.py", line 189, in execute_callable
    return self.python_callable(*self.op_args, **self.op_kwargs)
  File "/opt/airflow/dags/ETL.py", line 144, in person_dim
    d1 = d1[col]
  File "/home/airflow/.local/lib/python3.7/site-packages/pandas/core/frame.py", line 3464, in __getitem__
    indexer = self.loc._get_listlike_indexer(key, axis=1)[1]
  File "/home/airflow/.local/lib/python3.7/site-packages/pandas/core/indexing.py", line 1314, in _get_listlike_indexer
    self._validate_read_indexer(keyarr, indexer, axis)
  File "/home/airflow/.local/lib/python3.7/site-packages/pandas/core/indexing.py", line 1377, in _validate_read_indexer
    raise KeyError(f"{not_found} not in index")
KeyError: "['user_type', 'city'] not in index"
[2022-10-06T13:14:40.616+0000] {taskinstance.py:1412} INFO - Marking task as FAILED. dag_id=vecap_etl, task_id=person_dim, execution_date=20221006T131351, start_date=20221006T131427, end_date=20221006T131440
[2022-10-06T13:14:40.634+0000] {standard_task_runner.py:97} ERROR - Failed to execute job 198 for task person_dim ("['user_type', 'city'] not in index"; 3211)
[2022-10-06T13:14:40.672+0000] {local_task_job.py:156} INFO - Task exited with return code 1
