[2022-09-12T11:51:03.204+0000] {taskinstance.py:1171} INFO - Dependencies all met for <TaskInstance: test_etl.geo manual__2022-09-12T11:51:00.393263+00:00 [queued]>
[2022-09-12T11:51:03.223+0000] {taskinstance.py:1171} INFO - Dependencies all met for <TaskInstance: test_etl.geo manual__2022-09-12T11:51:00.393263+00:00 [queued]>
[2022-09-12T11:51:03.225+0000] {taskinstance.py:1368} INFO - 
--------------------------------------------------------------------------------
[2022-09-12T11:51:03.228+0000] {taskinstance.py:1369} INFO - Starting attempt 1 of 1
[2022-09-12T11:51:03.230+0000] {taskinstance.py:1370} INFO - 
--------------------------------------------------------------------------------
[2022-09-12T11:51:03.254+0000] {taskinstance.py:1389} INFO - Executing <Task(PythonOperator): geo> on 2022-09-12 11:51:00.393263+00:00
[2022-09-12T11:51:03.264+0000] {standard_task_runner.py:52} INFO - Started process 21619 to run task
[2022-09-12T11:51:03.271+0000] {standard_task_runner.py:79} INFO - Running: ['***', 'tasks', 'run', 'test_etl', 'geo', 'manual__2022-09-12T11:51:00.393263+00:00', '--job-id', '72', '--raw', '--subdir', 'DAGS_FOLDER/test_dag.py', '--cfg-path', '/tmp/tmpo8_jivq7', '--error-file', '/tmp/tmpbe3vqhnx']
[2022-09-12T11:51:03.275+0000] {standard_task_runner.py:80} INFO - Job 72: Subtask geo
[2022-09-12T11:51:03.427+0000] {task_command.py:371} INFO - Running <TaskInstance: test_etl.geo manual__2022-09-12T11:51:00.393263+00:00 [running]> on host 0d275337f52b
[2022-09-12T11:51:03.716+0000] {taskinstance.py:1583} INFO - Exporting the following env vars:
AIRFLOW_CTX_DAG_EMAIL=admin@vecap.com
AIRFLOW_CTX_DAG_OWNER=***
AIRFLOW_CTX_DAG_ID=test_etl
AIRFLOW_CTX_TASK_ID=geo
AIRFLOW_CTX_EXECUTION_DATE=2022-09-12T11:51:00.393263+00:00
AIRFLOW_CTX_TRY_NUMBER=1
AIRFLOW_CTX_DAG_RUN_ID=manual__2022-09-12T11:51:00.393263+00:00
[2022-09-12T11:51:15.208+0000] {taskinstance.py:1902} ERROR - Task failed with exception
Traceback (most recent call last):
  File "/home/airflow/.local/lib/python3.7/site-packages/sqlalchemy/engine/base.py", line 1783, in _execute_context
    cursor, statement, parameters, context
  File "/home/airflow/.local/lib/python3.7/site-packages/sqlalchemy/dialects/postgresql/psycopg2.py", line 957, in do_executemany
    **kwargs
  File "/home/airflow/.local/lib/python3.7/site-packages/psycopg2/extras.py", line 1270, in execute_values
    cur.execute(b''.join(parts))
psycopg2.errors.NotNullViolation: null value in column "country_code" of relation "geography_dim" violates not-null constraint
DETAIL:  Failing row contains (2, Ogun, 120003, null, Ghana, 2022-09-12 00:00:00+00, 2022-09-12 11:51:14.966647+00).


The above exception was the direct cause of the following exception:

Traceback (most recent call last):
  File "/home/airflow/.local/lib/python3.7/site-packages/airflow/operators/python.py", line 171, in execute
    return_value = self.execute_callable()
  File "/home/airflow/.local/lib/python3.7/site-packages/airflow/operators/python.py", line 189, in execute_callable
    return self.python_callable(*self.op_args, **self.op_kwargs)
  File "/opt/airflow/dags/test_dag.py", line 64, in geo_dim
    return dp.to_sql('geography_dim', con=db_target_conn, schema = scht, if_exists='append', index=False)
  File "/home/airflow/.local/lib/python3.7/site-packages/pandas/core/generic.py", line 2882, in to_sql
    method=method,
  File "/home/airflow/.local/lib/python3.7/site-packages/pandas/io/sql.py", line 728, in to_sql
    **engine_kwargs,
  File "/home/airflow/.local/lib/python3.7/site-packages/pandas/io/sql.py", line 1770, in to_sql
    **engine_kwargs,
  File "/home/airflow/.local/lib/python3.7/site-packages/pandas/io/sql.py", line 1350, in insert_records
    raise err
  File "/home/airflow/.local/lib/python3.7/site-packages/pandas/io/sql.py", line 1340, in insert_records
    table.insert(chunksize=chunksize, method=method)
  File "/home/airflow/.local/lib/python3.7/site-packages/pandas/io/sql.py", line 967, in insert
    exec_insert(conn, keys, chunk_iter)
  File "/home/airflow/.local/lib/python3.7/site-packages/pandas/io/sql.py", line 882, in _execute_insert
    conn.execute(self.table.insert(), data)
  File "/home/airflow/.local/lib/python3.7/site-packages/sqlalchemy/engine/base.py", line 1289, in execute
    return meth(self, multiparams, params, _EMPTY_EXECUTION_OPTS)
  File "/home/airflow/.local/lib/python3.7/site-packages/sqlalchemy/sql/elements.py", line 326, in _execute_on_connection
    self, multiparams, params, execution_options
  File "/home/airflow/.local/lib/python3.7/site-packages/sqlalchemy/engine/base.py", line 1491, in _execute_clauseelement
    cache_hit=cache_hit,
  File "/home/airflow/.local/lib/python3.7/site-packages/sqlalchemy/engine/base.py", line 1846, in _execute_context
    e, statement, parameters, cursor, context
  File "/home/airflow/.local/lib/python3.7/site-packages/sqlalchemy/engine/base.py", line 2027, in _handle_dbapi_exception
    sqlalchemy_exception, with_traceback=exc_info[2], from_=e
  File "/home/airflow/.local/lib/python3.7/site-packages/sqlalchemy/util/compat.py", line 207, in raise_
    raise exception
  File "/home/airflow/.local/lib/python3.7/site-packages/sqlalchemy/engine/base.py", line 1783, in _execute_context
    cursor, statement, parameters, context
  File "/home/airflow/.local/lib/python3.7/site-packages/sqlalchemy/dialects/postgresql/psycopg2.py", line 957, in do_executemany
    **kwargs
  File "/home/airflow/.local/lib/python3.7/site-packages/psycopg2/extras.py", line 1270, in execute_values
    cur.execute(b''.join(parts))
sqlalchemy.exc.IntegrityError: (psycopg2.errors.NotNullViolation) null value in column "country_code" of relation "geography_dim" violates not-null constraint
DETAIL:  Failing row contains (2, Ogun, 120003, null, Ghana, 2022-09-12 00:00:00+00, 2022-09-12 11:51:14.966647+00).

[SQL: INSERT INTO rccghge.geography_dim (state_province, zipcode, country_code, country_name, load_date) VALUES (%(state_province)s, %(zipcode)s, %(country_code)s, %(country_name)s, %(load_date)s)]
[parameters: ({'state_province': 'Ogun', 'zipcode': '120003', 'country_code': None, 'country_name': 'Ghana', 'load_date': datetime.date(2022, 9, 12)}, {'state_province': 'Lagos', 'zipcode': '105102', 'country_code': 'ng', 'country_name': 'Nigeria', 'load_date': datetime.date(2022, 9, 12)}, {'state_province': 'Qarku i Elbasanit', 'zipcode': '100031', 'country_code': 'al', 'country_name': 'Albania', 'load_date': datetime.date(2022, 9, 12)}, {'state_province': 'Sweden', 'zipcode': '123321', 'country_code': None, 'country_name': 'Gambia', 'load_date': datetime.date(2022, 9, 12)}, {'state_province': '2317', 'zipcode': '1234', 'country_code': None, 'country_name': 'ng', 'load_date': datetime.date(2022, 9, 12)}, {'state_province': 'Faryab Province', 'zipcode': '105102', 'country_code': 'af', 'country_name': 'Afghanistan', 'load_date': datetime.date(2022, 9, 12)}, {'state_province': 'Cabinda', 'zipcode': '102034', 'country_code': 'ag', 'country_name': 'Angola', 'load_date': datetime.date(2022, 9, 12)}, {'state_province': 'England', 'zipcode': '100000', 'country_code': 'eg', 'country_name': 'Great Britain (UK)', 'load_date': datetime.date(2022, 9, 12)}  ... displaying 10 of 13 total bound parameter sets ...  {'state_province': '3495', 'zipcode': '1234', 'country_code': 'ng', 'country_name': 'us', 'load_date': datetime.date(2022, 9, 12)}, {'state_province': 'Badakhshan', 'zipcode': '105102', 'country_code': 'ng', 'country_name': 'Afghanistan', 'load_date': datetime.date(2022, 9, 12)})]
(Background on this error at: https://sqlalche.me/e/14/gkpj)
[2022-09-12T11:51:15.233+0000] {taskinstance.py:1412} INFO - Marking task as FAILED. dag_id=test_etl, task_id=geo, execution_date=20220912T115100, start_date=20220912T115103, end_date=20220912T115115
[2022-09-12T11:51:15.255+0000] {standard_task_runner.py:97} ERROR - Failed to execute job 72 for task geo ((psycopg2.errors.NotNullViolation) null value in column "country_code" of relation "geography_dim" violates not-null constraint
DETAIL:  Failing row contains (2, Ogun, 120003, null, Ghana, 2022-09-12 00:00:00+00, 2022-09-12 11:51:14.966647+00).

[SQL: INSERT INTO rccghge.geography_dim (state_province, zipcode, country_code, country_name, load_date) VALUES (%(state_province)s, %(zipcode)s, %(country_code)s, %(country_name)s, %(load_date)s)]
[parameters: ({'state_province': 'Ogun', 'zipcode': '120003', 'country_code': None, 'country_name': 'Ghana', 'load_date': datetime.date(2022, 9, 12)}, {'state_province': 'Lagos', 'zipcode': '105102', 'country_code': 'ng', 'country_name': 'Nigeria', 'load_date': datetime.date(2022, 9, 12)}, {'state_province': 'Qarku i Elbasanit', 'zipcode': '100031', 'country_code': 'al', 'country_name': 'Albania', 'load_date': datetime.date(2022, 9, 12)}, {'state_province': 'Sweden', 'zipcode': '123321', 'country_code': None, 'country_name': 'Gambia', 'load_date': datetime.date(2022, 9, 12)}, {'state_province': '2317', 'zipcode': '1234', 'country_code': None, 'country_name': 'ng', 'load_date': datetime.date(2022, 9, 12)}, {'state_province': 'Faryab Province', 'zipcode': '105102', 'country_code': 'af', 'country_name': 'Afghanistan', 'load_date': datetime.date(2022, 9, 12)}, {'state_province': 'Cabinda', 'zipcode': '102034', 'country_code': 'ag', 'country_name': 'Angola', 'load_date': datetime.date(2022, 9, 12)}, {'state_province': 'England', 'zipcode': '100000', 'country_code': 'eg', 'country_name': 'Great Britain (UK)', 'load_date': datetime.date(2022, 9, 12)}  ... displaying 10 of 13 total bound parameter sets ...  {'state_province': '3495', 'zipcode': '1234', 'country_code': 'ng', 'country_name': 'us', 'load_date': datetime.date(2022, 9, 12)}, {'state_province': 'Badakhshan', 'zipcode': '105102', 'country_code': 'ng', 'country_name': 'Afghanistan', 'load_date': datetime.date(2022, 9, 12)})]
(Background on this error at: https://sqlalche.me/e/14/gkpj); 21619)
[2022-09-12T11:51:15.286+0000] {local_task_job.py:156} INFO - Task exited with return code 1
[2022-09-12T11:51:15.342+0000] {local_task_job.py:279} INFO - 0 downstream tasks scheduled from follow-on schedule check
