[2022-10-06T14:54:03.569+0000] {taskinstance.py:1171} INFO - Dependencies all met for <TaskInstance: vecap_etl.fam_dim manual__2022-10-06T14:53:43.395110+00:00 [queued]>
[2022-10-06T14:54:03.586+0000] {taskinstance.py:1171} INFO - Dependencies all met for <TaskInstance: vecap_etl.fam_dim manual__2022-10-06T14:53:43.395110+00:00 [queued]>
[2022-10-06T14:54:03.588+0000] {taskinstance.py:1368} INFO - 
--------------------------------------------------------------------------------
[2022-10-06T14:54:03.591+0000] {taskinstance.py:1369} INFO - Starting attempt 1 of 1
[2022-10-06T14:54:03.593+0000] {taskinstance.py:1370} INFO - 
--------------------------------------------------------------------------------
[2022-10-06T14:54:03.621+0000] {taskinstance.py:1389} INFO - Executing <Task(PythonOperator): fam_dim> on 2022-10-06 14:53:43.395110+00:00
[2022-10-06T14:54:03.631+0000] {standard_task_runner.py:52} INFO - Started process 8485 to run task
[2022-10-06T14:54:03.640+0000] {standard_task_runner.py:79} INFO - Running: ['***', 'tasks', 'run', 'vecap_etl', 'fam_dim', 'manual__2022-10-06T14:53:43.395110+00:00', '--job-id', '224', '--raw', '--subdir', 'DAGS_FOLDER/c_dag.py', '--cfg-path', '/tmp/tmp4uwbhkk4', '--error-file', '/tmp/tmpi0qfngna']
[2022-10-06T14:54:03.685+0000] {standard_task_runner.py:80} INFO - Job 224: Subtask fam_dim
[2022-10-06T14:54:03.986+0000] {task_command.py:371} INFO - Running <TaskInstance: vecap_etl.fam_dim manual__2022-10-06T14:53:43.395110+00:00 [running]> on host a41ad1c55a2c
[2022-10-06T14:54:04.237+0000] {taskinstance.py:1583} INFO - Exporting the following env vars:
AIRFLOW_CTX_DAG_EMAIL=admin@vecap.com
AIRFLOW_CTX_DAG_OWNER=***
AIRFLOW_CTX_DAG_ID=vecap_etl
AIRFLOW_CTX_TASK_ID=fam_dim
AIRFLOW_CTX_EXECUTION_DATE=2022-10-06T14:53:43.395110+00:00
AIRFLOW_CTX_TRY_NUMBER=1
AIRFLOW_CTX_DAG_RUN_ID=manual__2022-10-06T14:53:43.395110+00:00
[2022-10-06T14:54:18.152+0000] {taskinstance.py:1902} ERROR - Task failed with exception
Traceback (most recent call last):
  File "/home/airflow/.local/lib/python3.7/site-packages/sqlalchemy/engine/base.py", line 1783, in _execute_context
    cursor, statement, parameters, context
  File "/home/airflow/.local/lib/python3.7/site-packages/sqlalchemy/dialects/postgresql/psycopg2.py", line 957, in do_executemany
    **kwargs
  File "/home/airflow/.local/lib/python3.7/site-packages/psycopg2/extras.py", line 1270, in execute_values
    cur.execute(b''.join(parts))
psycopg2.errors.InvalidTextRepresentation: invalid input syntax for type numeric: "NA"
LINE 1: ...b-b2ae-4960-86e8-3b7a4c1b42d8'::uuid, 'Suleiman', 'NA', 1, '...
                                                             ^


The above exception was the direct cause of the following exception:

Traceback (most recent call last):
  File "/opt/airflow/dags/ETL.py", line 208, in fam_dim
    faz.to_sql('fam_dim', con=target ,schema = sch, if_exists ='append', index=False)
  File "/home/airflow/.local/lib/python3.7/site-packages/pandas/core/generic.py", line 2882, in to_sql
    method=method,
  File "/home/airflow/.local/lib/python3.7/site-packages/pandas/io/sql.py", line 728, in to_sql
    **engine_kwargs,
  File "/home/airflow/.local/lib/python3.7/site-packages/pandas/io/sql.py", line 1770, in to_sql
    **engine_kwargs,
  File "/home/airflow/.local/lib/python3.7/site-packages/pandas/io/sql.py", line 1350, in insert_records
    raise err
  File "/home/airflow/.local/lib/python3.7/site-packages/pandas/io/sql.py", line 1340, in insert_records
    table.insert(chunksize=chunksize, method=method)
  File "/home/airflow/.local/lib/python3.7/site-packages/pandas/io/sql.py", line 967, in insert
    exec_insert(conn, keys, chunk_iter)
  File "/home/airflow/.local/lib/python3.7/site-packages/pandas/io/sql.py", line 882, in _execute_insert
    conn.execute(self.table.insert(), data)
  File "/home/airflow/.local/lib/python3.7/site-packages/sqlalchemy/engine/base.py", line 1289, in execute
    return meth(self, multiparams, params, _EMPTY_EXECUTION_OPTS)
  File "/home/airflow/.local/lib/python3.7/site-packages/sqlalchemy/sql/elements.py", line 326, in _execute_on_connection
    self, multiparams, params, execution_options
  File "/home/airflow/.local/lib/python3.7/site-packages/sqlalchemy/engine/base.py", line 1491, in _execute_clauseelement
    cache_hit=cache_hit,
  File "/home/airflow/.local/lib/python3.7/site-packages/sqlalchemy/engine/base.py", line 1846, in _execute_context
    e, statement, parameters, cursor, context
  File "/home/airflow/.local/lib/python3.7/site-packages/sqlalchemy/engine/base.py", line 2027, in _handle_dbapi_exception
    sqlalchemy_exception, with_traceback=exc_info[2], from_=e
  File "/home/airflow/.local/lib/python3.7/site-packages/sqlalchemy/util/compat.py", line 207, in raise_
    raise exception
  File "/home/airflow/.local/lib/python3.7/site-packages/sqlalchemy/engine/base.py", line 1783, in _execute_context
    cursor, statement, parameters, context
  File "/home/airflow/.local/lib/python3.7/site-packages/sqlalchemy/dialects/postgresql/psycopg2.py", line 957, in do_executemany
    **kwargs
  File "/home/airflow/.local/lib/python3.7/site-packages/psycopg2/extras.py", line 1270, in execute_values
    cur.execute(b''.join(parts))
sqlalchemy.exc.DataError: (psycopg2.errors.InvalidTextRepresentation) invalid input syntax for type numeric: "NA"
LINE 1: ...b-b2ae-4960-86e8-3b7a4c1b42d8'::uuid, 'Suleiman', 'NA', 1, '...
                                                             ^

[SQL: INSERT INTO rccghge.fam_dim (fam_key, fam_id, fam_name, no_fam_members, geography_key, fam_city, fam_wedding_date, fam_date_created, load_date) VALUES (%(fam_key)s, %(fam_id)s, %(fam_name)s, %(no_fam_members)s, %(geography_key)s, %(fam_city)s, %(fam_wedding_date)s, %(fam_date_created)s, %(load_date)s)]
[parameters: ({'fam_key': 1, 'fam_id': UUID('029277db-b2ae-4960-86e8-3b7a4c1b42d8'), 'fam_name': 'Suleiman', 'no_fam_members': 'NA', 'geography_key': 1, 'fam_city': 'Lagos', 'fam_wedding_date': 'NA', 'fam_date_created': datetime.datetime(2022, 10, 5, 8, 54, 1, 778000, tzinfo=datetime.timezone.utc), 'load_date': datetime.datetime(2022, 10, 6, 14, 54, 15, 122710)}, {'fam_key': 2, 'fam_id': UUID('50bc99f0-d3d7-40dd-bdc7-ee948c5e264c'), 'fam_name': 'Ogedengbe', 'no_fam_members': 'NA', 'geography_key': 1, 'fam_city': 'Ikorodu', 'fam_wedding_date': 'NA', 'fam_date_created': datetime.datetime(2022, 10, 5, 9, 18, 8, 755000, tzinfo=datetime.timezone.utc), 'load_date': datetime.datetime(2022, 10, 6, 14, 54, 15, 122710)}, {'fam_key': 3, 'fam_id': UUID('d22b897b-9118-413c-b416-b2cf1ef8731a'), 'fam_name': 'Akindele', 'no_fam_members': 'NA', 'geography_key': 3, 'fam_city': 'ipaja', 'fam_wedding_date': 'NA', 'fam_date_created': datetime.datetime(2022, 10, 5, 14, 20, 25, 461000, tzinfo=datetime.timezone.utc), 'load_date': datetime.datetime(2022, 10, 6, 14, 54, 15, 122710)}, {'fam_key': 4, 'fam_id': UUID('75fd9687-acc2-4ac5-8bfc-f0e7857e56d1'), 'fam_name': 'Chukwu', 'no_fam_members': 'NA', 'geography_key': 3, 'fam_city': 'yaba', 'fam_wedding_date': 'NA', 'fam_date_created': datetime.datetime(2022, 10, 6, 4, 51, 3, 66000, tzinfo=datetime.timezone.utc), 'load_date': datetime.datetime(2022, 10, 6, 14, 54, 15, 122710)}, {'fam_key': 5, 'fam_id': UUID('fbb7b728-e419-4740-9c9d-74abb25f02b6'), 'fam_name': 'Oladipupo', 'no_fam_members': 'NA', 'geography_key': 3, 'fam_city': 'yaba', 'fam_wedding_date': 'NA', 'fam_date_created': datetime.datetime(2022, 10, 6, 10, 2, 40, 964000, tzinfo=datetime.timezone.utc), 'load_date': datetime.datetime(2022, 10, 6, 14, 54, 15, 122710)})]
(Background on this error at: https://sqlalche.me/e/14/9h9h)

During handling of the above exception, another exception occurred:

Traceback (most recent call last):
  File "/home/airflow/.local/lib/python3.7/site-packages/sqlalchemy/engine/base.py", line 1783, in _execute_context
    cursor, statement, parameters, context
  File "/home/airflow/.local/lib/python3.7/site-packages/sqlalchemy/dialects/postgresql/psycopg2.py", line 957, in do_executemany
    **kwargs
  File "/home/airflow/.local/lib/python3.7/site-packages/psycopg2/extras.py", line 1270, in execute_values
    cur.execute(b''.join(parts))
psycopg2.errors.UndefinedColumn: column "fam_id" of relation "person_dim" does not exist
LINE 1: INSERT INTO rccghge.person_dim (fam_key, fam_id, fam_name, n...
                                                 ^


The above exception was the direct cause of the following exception:

Traceback (most recent call last):
  File "/home/airflow/.local/lib/python3.7/site-packages/airflow/operators/python.py", line 171, in execute
    return_value = self.execute_callable()
  File "/home/airflow/.local/lib/python3.7/site-packages/airflow/operators/python.py", line 189, in execute_callable
    return self.python_callable(*self.op_args, **self.op_kwargs)
  File "/opt/airflow/dags/ETL.py", line 210, in fam_dim
    fam.to_sql('person_dim', con=target ,schema = sch, if_exists ='append', index=False)
  File "/home/airflow/.local/lib/python3.7/site-packages/pandas/core/generic.py", line 2882, in to_sql
    method=method,
  File "/home/airflow/.local/lib/python3.7/site-packages/pandas/io/sql.py", line 728, in to_sql
    **engine_kwargs,
  File "/home/airflow/.local/lib/python3.7/site-packages/pandas/io/sql.py", line 1770, in to_sql
    **engine_kwargs,
  File "/home/airflow/.local/lib/python3.7/site-packages/pandas/io/sql.py", line 1350, in insert_records
    raise err
  File "/home/airflow/.local/lib/python3.7/site-packages/pandas/io/sql.py", line 1340, in insert_records
    table.insert(chunksize=chunksize, method=method)
  File "/home/airflow/.local/lib/python3.7/site-packages/pandas/io/sql.py", line 967, in insert
    exec_insert(conn, keys, chunk_iter)
  File "/home/airflow/.local/lib/python3.7/site-packages/pandas/io/sql.py", line 882, in _execute_insert
    conn.execute(self.table.insert(), data)
  File "/home/airflow/.local/lib/python3.7/site-packages/sqlalchemy/engine/base.py", line 1289, in execute
    return meth(self, multiparams, params, _EMPTY_EXECUTION_OPTS)
  File "/home/airflow/.local/lib/python3.7/site-packages/sqlalchemy/sql/elements.py", line 326, in _execute_on_connection
    self, multiparams, params, execution_options
  File "/home/airflow/.local/lib/python3.7/site-packages/sqlalchemy/engine/base.py", line 1491, in _execute_clauseelement
    cache_hit=cache_hit,
  File "/home/airflow/.local/lib/python3.7/site-packages/sqlalchemy/engine/base.py", line 1846, in _execute_context
    e, statement, parameters, cursor, context
  File "/home/airflow/.local/lib/python3.7/site-packages/sqlalchemy/engine/base.py", line 2027, in _handle_dbapi_exception
    sqlalchemy_exception, with_traceback=exc_info[2], from_=e
  File "/home/airflow/.local/lib/python3.7/site-packages/sqlalchemy/util/compat.py", line 207, in raise_
    raise exception
  File "/home/airflow/.local/lib/python3.7/site-packages/sqlalchemy/engine/base.py", line 1783, in _execute_context
    cursor, statement, parameters, context
  File "/home/airflow/.local/lib/python3.7/site-packages/sqlalchemy/dialects/postgresql/psycopg2.py", line 957, in do_executemany
    **kwargs
  File "/home/airflow/.local/lib/python3.7/site-packages/psycopg2/extras.py", line 1270, in execute_values
    cur.execute(b''.join(parts))
sqlalchemy.exc.ProgrammingError: (psycopg2.errors.UndefinedColumn) column "fam_id" of relation "person_dim" does not exist
LINE 1: INSERT INTO rccghge.person_dim (fam_key, fam_id, fam_name, n...
                                                 ^

[SQL: INSERT INTO rccghge.person_dim (fam_key, fam_id, fam_name, no_fam_members, geography_key, fam_city, fam_wedding_date, fam_date_created, load_date) VALUES (%(fam_key)s, %(fam_id)s, %(fam_name)s, %(no_fam_members)s, %(geography_key)s, %(fam_city)s, %(fam_wedding_date)s, %(fam_date_created)s, %(load_date)s)]
[parameters: ({'fam_key': 1, 'fam_id': UUID('029277db-b2ae-4960-86e8-3b7a4c1b42d8'), 'fam_name': 'Suleiman', 'no_fam_members': 'NA', 'geography_key': 1, 'fam_city': 'Lagos', 'fam_wedding_date': 'NA', 'fam_date_created': datetime.datetime(2022, 10, 5, 8, 54, 1, 778000, tzinfo=datetime.timezone.utc), 'load_date': datetime.datetime(2022, 10, 6, 14, 54, 15, 122710)}, {'fam_key': 2, 'fam_id': UUID('50bc99f0-d3d7-40dd-bdc7-ee948c5e264c'), 'fam_name': 'Ogedengbe', 'no_fam_members': 'NA', 'geography_key': 1, 'fam_city': 'Ikorodu', 'fam_wedding_date': 'NA', 'fam_date_created': datetime.datetime(2022, 10, 5, 9, 18, 8, 755000, tzinfo=datetime.timezone.utc), 'load_date': datetime.datetime(2022, 10, 6, 14, 54, 15, 122710)}, {'fam_key': 3, 'fam_id': UUID('d22b897b-9118-413c-b416-b2cf1ef8731a'), 'fam_name': 'Akindele', 'no_fam_members': 'NA', 'geography_key': 3, 'fam_city': 'ipaja', 'fam_wedding_date': 'NA', 'fam_date_created': datetime.datetime(2022, 10, 5, 14, 20, 25, 461000, tzinfo=datetime.timezone.utc), 'load_date': datetime.datetime(2022, 10, 6, 14, 54, 15, 122710)}, {'fam_key': 4, 'fam_id': UUID('75fd9687-acc2-4ac5-8bfc-f0e7857e56d1'), 'fam_name': 'Chukwu', 'no_fam_members': 'NA', 'geography_key': 3, 'fam_city': 'yaba', 'fam_wedding_date': 'NA', 'fam_date_created': datetime.datetime(2022, 10, 6, 4, 51, 3, 66000, tzinfo=datetime.timezone.utc), 'load_date': datetime.datetime(2022, 10, 6, 14, 54, 15, 122710)}, {'fam_key': 5, 'fam_id': UUID('fbb7b728-e419-4740-9c9d-74abb25f02b6'), 'fam_name': 'Oladipupo', 'no_fam_members': 'NA', 'geography_key': 3, 'fam_city': 'yaba', 'fam_wedding_date': 'NA', 'fam_date_created': datetime.datetime(2022, 10, 6, 10, 2, 40, 964000, tzinfo=datetime.timezone.utc), 'load_date': datetime.datetime(2022, 10, 6, 14, 54, 15, 122710)})]
(Background on this error at: https://sqlalche.me/e/14/f405)
[2022-10-06T14:54:18.187+0000] {taskinstance.py:1412} INFO - Marking task as FAILED. dag_id=vecap_etl, task_id=fam_dim, execution_date=20221006T145343, start_date=20221006T145403, end_date=20221006T145418
[2022-10-06T14:54:18.205+0000] {standard_task_runner.py:97} ERROR - Failed to execute job 224 for task fam_dim ((psycopg2.errors.UndefinedColumn) column "fam_id" of relation "person_dim" does not exist
LINE 1: INSERT INTO rccghge.person_dim (fam_key, fam_id, fam_name, n...
                                                 ^

[SQL: INSERT INTO rccghge.person_dim (fam_key, fam_id, fam_name, no_fam_members, geography_key, fam_city, fam_wedding_date, fam_date_created, load_date) VALUES (%(fam_key)s, %(fam_id)s, %(fam_name)s, %(no_fam_members)s, %(geography_key)s, %(fam_city)s, %(fam_wedding_date)s, %(fam_date_created)s, %(load_date)s)]
[parameters: ({'fam_key': 1, 'fam_id': UUID('029277db-b2ae-4960-86e8-3b7a4c1b42d8'), 'fam_name': 'Suleiman', 'no_fam_members': 'NA', 'geography_key': 1, 'fam_city': 'Lagos', 'fam_wedding_date': 'NA', 'fam_date_created': datetime.datetime(2022, 10, 5, 8, 54, 1, 778000, tzinfo=datetime.timezone.utc), 'load_date': datetime.datetime(2022, 10, 6, 14, 54, 15, 122710)}, {'fam_key': 2, 'fam_id': UUID('50bc99f0-d3d7-40dd-bdc7-ee948c5e264c'), 'fam_name': 'Ogedengbe', 'no_fam_members': 'NA', 'geography_key': 1, 'fam_city': 'Ikorodu', 'fam_wedding_date': 'NA', 'fam_date_created': datetime.datetime(2022, 10, 5, 9, 18, 8, 755000, tzinfo=datetime.timezone.utc), 'load_date': datetime.datetime(2022, 10, 6, 14, 54, 15, 122710)}, {'fam_key': 3, 'fam_id': UUID('d22b897b-9118-413c-b416-b2cf1ef8731a'), 'fam_name': 'Akindele', 'no_fam_members': 'NA', 'geography_key': 3, 'fam_city': 'ipaja', 'fam_wedding_date': 'NA', 'fam_date_created': datetime.datetime(2022, 10, 5, 14, 20, 25, 461000, tzinfo=datetime.timezone.utc), 'load_date': datetime.datetime(2022, 10, 6, 14, 54, 15, 122710)}, {'fam_key': 4, 'fam_id': UUID('75fd9687-acc2-4ac5-8bfc-f0e7857e56d1'), 'fam_name': 'Chukwu', 'no_fam_members': 'NA', 'geography_key': 3, 'fam_city': 'yaba', 'fam_wedding_date': 'NA', 'fam_date_created': datetime.datetime(2022, 10, 6, 4, 51, 3, 66000, tzinfo=datetime.timezone.utc), 'load_date': datetime.datetime(2022, 10, 6, 14, 54, 15, 122710)}, {'fam_key': 5, 'fam_id': UUID('fbb7b728-e419-4740-9c9d-74abb25f02b6'), 'fam_name': 'Oladipupo', 'no_fam_members': 'NA', 'geography_key': 3, 'fam_city': 'yaba', 'fam_wedding_date': 'NA', 'fam_date_created': datetime.datetime(2022, 10, 6, 10, 2, 40, 964000, tzinfo=datetime.timezone.utc), 'load_date': datetime.datetime(2022, 10, 6, 14, 54, 15, 122710)})]
(Background on this error at: https://sqlalche.me/e/14/f405); 8485)
[2022-10-06T14:54:18.242+0000] {local_task_job.py:156} INFO - Task exited with return code 1
