[2022-10-06T12:41:40.115+0000] {taskinstance.py:1171} INFO - Dependencies all met for <TaskInstance: vecap_etl.geography_dim manual__2022-10-06T12:41:33.101804+00:00 [queued]>
[2022-10-06T12:41:40.188+0000] {taskinstance.py:1171} INFO - Dependencies all met for <TaskInstance: vecap_etl.geography_dim manual__2022-10-06T12:41:33.101804+00:00 [queued]>
[2022-10-06T12:41:40.196+0000] {taskinstance.py:1368} INFO - 
--------------------------------------------------------------------------------
[2022-10-06T12:41:40.204+0000] {taskinstance.py:1369} INFO - Starting attempt 1 of 1
[2022-10-06T12:41:40.213+0000] {taskinstance.py:1370} INFO - 
--------------------------------------------------------------------------------
[2022-10-06T12:41:40.355+0000] {taskinstance.py:1389} INFO - Executing <Task(PythonOperator): geography_dim> on 2022-10-06 12:41:33.101804+00:00
[2022-10-06T12:41:40.444+0000] {standard_task_runner.py:52} INFO - Started process 601 to run task
[2022-10-06T12:41:40.505+0000] {standard_task_runner.py:79} INFO - Running: ['***', 'tasks', 'run', 'vecap_etl', 'geography_dim', 'manual__2022-10-06T12:41:33.101804+00:00', '--job-id', '177', '--raw', '--subdir', 'DAGS_FOLDER/c_dag.py', '--cfg-path', '/tmp/tmpjgij0fvo', '--error-file', '/tmp/tmp0xup3my4']
[2022-10-06T12:41:40.530+0000] {standard_task_runner.py:80} INFO - Job 177: Subtask geography_dim
[2022-10-06T12:41:40.985+0000] {task_command.py:371} INFO - Running <TaskInstance: vecap_etl.geography_dim manual__2022-10-06T12:41:33.101804+00:00 [running]> on host a41ad1c55a2c
[2022-10-06T12:41:41.380+0000] {taskinstance.py:1583} INFO - Exporting the following env vars:
AIRFLOW_CTX_DAG_EMAIL=admin@vecap.com
AIRFLOW_CTX_DAG_OWNER=***
AIRFLOW_CTX_DAG_ID=vecap_etl
AIRFLOW_CTX_TASK_ID=geography_dim
AIRFLOW_CTX_EXECUTION_DATE=2022-10-06T12:41:33.101804+00:00
AIRFLOW_CTX_TRY_NUMBER=1
AIRFLOW_CTX_DAG_RUN_ID=manual__2022-10-06T12:41:33.101804+00:00
[2022-10-06T12:41:54.563+0000] {taskinstance.py:1902} ERROR - Task failed with exception
Traceback (most recent call last):
  File "/home/airflow/.local/lib/python3.7/site-packages/sqlalchemy/engine/base.py", line 1783, in _execute_context
    cursor, statement, parameters, context
  File "/home/airflow/.local/lib/python3.7/site-packages/sqlalchemy/dialects/postgresql/psycopg2.py", line 957, in do_executemany
    **kwargs
  File "/home/airflow/.local/lib/python3.7/site-packages/psycopg2/extras.py", line 1270, in execute_values
    cur.execute(b''.join(parts))
psycopg2.errors.InvalidTextRepresentation: invalid input syntax for type numeric: "Not Set"
LINE 1: ...ry_code, country_name, load_date) VALUES ('2341', 'Not Set',...
                                                             ^


The above exception was the direct cause of the following exception:

Traceback (most recent call last):
  File "/home/airflow/.local/lib/python3.7/site-packages/airflow/operators/python.py", line 171, in execute
    return_value = self.execute_callable()
  File "/home/airflow/.local/lib/python3.7/site-packages/airflow/operators/python.py", line 189, in execute_callable
    return self.python_callable(*self.op_args, **self.op_kwargs)
  File "/opt/airflow/dags/ETL.py", line 85, in geo_dim
    return  dp.to_sql('geography_dim', con=target, schema = sch, if_exists='append', index=False)
  File "/home/airflow/.local/lib/python3.7/site-packages/pandas/core/generic.py", line 2882, in to_sql
    method=method,
  File "/home/airflow/.local/lib/python3.7/site-packages/pandas/io/sql.py", line 728, in to_sql
    **engine_kwargs,
  File "/home/airflow/.local/lib/python3.7/site-packages/pandas/io/sql.py", line 1770, in to_sql
    **engine_kwargs,
  File "/home/airflow/.local/lib/python3.7/site-packages/pandas/io/sql.py", line 1350, in insert_records
    raise err
  File "/home/airflow/.local/lib/python3.7/site-packages/pandas/io/sql.py", line 1340, in insert_records
    table.insert(chunksize=chunksize, method=method)
  File "/home/airflow/.local/lib/python3.7/site-packages/pandas/io/sql.py", line 967, in insert
    exec_insert(conn, keys, chunk_iter)
  File "/home/airflow/.local/lib/python3.7/site-packages/pandas/io/sql.py", line 882, in _execute_insert
    conn.execute(self.table.insert(), data)
  File "/home/airflow/.local/lib/python3.7/site-packages/sqlalchemy/engine/base.py", line 1289, in execute
    return meth(self, multiparams, params, _EMPTY_EXECUTION_OPTS)
  File "/home/airflow/.local/lib/python3.7/site-packages/sqlalchemy/sql/elements.py", line 326, in _execute_on_connection
    self, multiparams, params, execution_options
  File "/home/airflow/.local/lib/python3.7/site-packages/sqlalchemy/engine/base.py", line 1491, in _execute_clauseelement
    cache_hit=cache_hit,
  File "/home/airflow/.local/lib/python3.7/site-packages/sqlalchemy/engine/base.py", line 1846, in _execute_context
    e, statement, parameters, cursor, context
  File "/home/airflow/.local/lib/python3.7/site-packages/sqlalchemy/engine/base.py", line 2027, in _handle_dbapi_exception
    sqlalchemy_exception, with_traceback=exc_info[2], from_=e
  File "/home/airflow/.local/lib/python3.7/site-packages/sqlalchemy/util/compat.py", line 207, in raise_
    raise exception
  File "/home/airflow/.local/lib/python3.7/site-packages/sqlalchemy/engine/base.py", line 1783, in _execute_context
    cursor, statement, parameters, context
  File "/home/airflow/.local/lib/python3.7/site-packages/sqlalchemy/dialects/postgresql/psycopg2.py", line 957, in do_executemany
    **kwargs
  File "/home/airflow/.local/lib/python3.7/site-packages/psycopg2/extras.py", line 1270, in execute_values
    cur.execute(b''.join(parts))
sqlalchemy.exc.DataError: (psycopg2.errors.InvalidTextRepresentation) invalid input syntax for type numeric: "Not Set"
LINE 1: ...ry_code, country_name, load_date) VALUES ('2341', 'Not Set',...
                                                             ^

[SQL: INSERT INTO rccghge.geography_dim (state_province, zipcode, country_code, country_name, load_date) VALUES (%(state_province)s, %(zipcode)s, %(country_code)s, %(country_name)s, %(load_date)s)]
[parameters: ({'state_province': '2341', 'zipcode': 'Not Set', 'country_code': 'Not Set', 'country_name': 'ng', 'load_date': datetime.date(2022, 10, 6)}, {'state_province': 'Lagos State', 'zipcode': 'Not Set', 'country_code': 'Not Set', 'country_name': 'Nigeria', 'load_date': datetime.date(2022, 10, 6)})]
(Background on this error at: https://sqlalche.me/e/14/9h9h)
[2022-10-06T12:41:54.603+0000] {taskinstance.py:1412} INFO - Marking task as FAILED. dag_id=vecap_etl, task_id=geography_dim, execution_date=20221006T124133, start_date=20221006T124140, end_date=20221006T124154
[2022-10-06T12:41:54.625+0000] {standard_task_runner.py:97} ERROR - Failed to execute job 177 for task geography_dim ((psycopg2.errors.InvalidTextRepresentation) invalid input syntax for type numeric: "Not Set"
LINE 1: ...ry_code, country_name, load_date) VALUES ('2341', 'Not Set',...
                                                             ^

[SQL: INSERT INTO rccghge.geography_dim (state_province, zipcode, country_code, country_name, load_date) VALUES (%(state_province)s, %(zipcode)s, %(country_code)s, %(country_name)s, %(load_date)s)]
[parameters: ({'state_province': '2341', 'zipcode': 'Not Set', 'country_code': 'Not Set', 'country_name': 'ng', 'load_date': datetime.date(2022, 10, 6)}, {'state_province': 'Lagos State', 'zipcode': 'Not Set', 'country_code': 'Not Set', 'country_name': 'Nigeria', 'load_date': datetime.date(2022, 10, 6)})]
(Background on this error at: https://sqlalche.me/e/14/9h9h); 601)
[2022-10-06T12:41:54.647+0000] {local_task_job.py:156} INFO - Task exited with return code 1
